<?xml version="1.0"?>
<robot 
       xmlns:xacro="http://ros.org/wiki/xacro">

    <!-- common stuff -->
    <xacro:include filename="$(find ipa325_robot_descriptions)/urdf/kr16/gazebo.urdf.xacro" />
    <xacro:include filename="$(find ipa325_robot_descriptions)/urdf/kr16/kr16.gazebo.xacro" />
    <xacro:include filename="$(find ipa325_robot_descriptions)/urdf/kr16/kr16.transmission.xacro" />

    <xacro:property name="pi" value="3.14159265" />

    <xacro:macro name="ipa325_kr16" params="prefix parent r:=1.0 g:=0.5 b:=0.0 *origin">

        <joint name="${prefix}joint_0" type="fixed" >
            <xacro:insert_block name="origin" />
            <parent link="${parent}" />
            <child link="${prefix}base" />
        </joint>

        <link name="${prefix}base">
            <inertial>
                <origin xyz="0 0 0" rpy="0 0 0"/>
                <mass value="2"/>
                <inertia ixx="0.01" ixy="0" ixz="0" iyy="0.01" iyz="0" izz="0.01" />
            </inertial>

            <visual>
                <origin xyz="0 0 0" rpy="0 0 0" />
                <geometry>
                    <!--cylinder radius="0.060" length="0.30"/-->
                    <mesh filename="package://ipa325_robot_descriptions/meshes/kr16/joint_0.stl" />
                </geometry>
                <material name="Black" />
            </visual>

            <collision>
                <origin xyz="0 0 0" rpy="0 0 0" />
                <geometry>
                    <mesh filename="package://ipa325_robot_descriptions/meshes/kr16/joint_0.stl" />
                </geometry>
            </collision>
        </link>

        <!-- joint between arm_0_link and arm_1_link -->
        <joint name="${prefix}joint_1" type="revolute">
        <origin xyz="0 0 0.390" rpy="${pi} 0 0"/>
            <parent link="${prefix}base"/>
            <child link="${prefix}link_1"/>
            <axis xyz="0 0 1"/>
            <dynamics damping="10" />
            <limit effort="200" velocity="1.9634" lower="-2.9670" upper="2.9670"/>
            <safety_controller k_position="20" k_velocity="50" soft_lower_limit="${-2.9670 + 0.01}" soft_upper_limit="${2.9670 - 0.01}" />
        </joint>
        
        <link name="${prefix}link_1">
            <inertial>
                <origin xyz="0 0 0" rpy="0 0 0" />
                <!--mass value="5.9907"/-->
                <mass value="2"/>
                <inertia ixx="0.01" ixy="0" ixz="0" iyy="0.01" iyz="0" izz="0.01" />
            </inertial>
            
            <visual>
                <origin xyz="0 0 0" rpy="0 0 0" />
                <geometry>
                    <mesh filename="package://ipa325_robot_descriptions/meshes/kr16/joint_1.stl" />
                </geometry>
                <material name="lbr-material">
                    <color rgba="${r} ${g} ${b} 1.0"/>
                </material>
            </visual>
            
            <collision>
                <origin xyz="0 0 0" rpy="0 0 0" />
                <geometry>
                    <mesh filename="package://ipa325_robot_descriptions/meshes/kr16/joint_1.stl" />
                </geometry>
            </collision>
        </link>

        <!-- joint between arm_1_link and arm_2_link -->    
        <joint name="${prefix}joint_2" type="revolute">
            <origin xyz="0.260 0.0 -0.285" rpy="${pi/2} 0 0"/>
            <parent link="${prefix}link_1"/>
            <child link="${prefix}link_2"/>
            <axis xyz="0 0 1"/>
            <dynamics damping="10" />
            <limit effort="200" velocity="1.9634" lower="-2.0943" upper="2.0943"/>
            <safety_controller k_position="20" k_velocity="50" soft_lower_limit="${-2.0943 + 0.01}" soft_upper_limit="${2.0943 - 0.01}" />
        </joint>
        
        <link name="${prefix}link_2">
            <inertial>
                <origin xyz="0 0 0" rpy="0 0 0"/>
                <mass value="2"/>
                <inertia ixx="0.03" ixy="0" ixz="0" iyy="0.03" iyz="0" izz="0.03" />
            </inertial>
            
            <visual>
                <origin xyz="0 0 0" rpy="0 0 0" />
                <geometry>
                    <mesh filename="package://ipa325_robot_descriptions/meshes/kr16/joint_2.stl" />
                </geometry>
                <material name="lbr-material">
                    <color rgba="${r} ${g} ${b} 1.0"/>
                </material>
            </visual>
            
            <collision>
                <origin xyz="0 0 0" rpy="0 0 0" />
                <geometry>
                    <mesh filename="package://ipa325_robot_descriptions/meshes/kr16/joint_2.stl" />
                </geometry>
            </collision>
        </link>

        <!-- joint between arm_2_link and arm_3_link -->    
        <joint name="${prefix}joint_3" type="revolute">
            <origin xyz="0.680 0 0" rpy="0 0 0"/>
            <parent link="${prefix}link_2"/>
            <child link="${prefix}link_3"/>
            <axis xyz="0 0 1"/>
            <dynamics damping="5" />
            <limit effort="100" velocity="1.9634" lower="-2.9670" upper="2.9670"/>
            <safety_controller k_position="20" k_velocity="25" soft_lower_limit="${-2.9670 + 0.01}" soft_upper_limit="${2.9670 - 0.01}" />
        </joint>

        <link name="${prefix}link_3">
            <inertial>
                <origin xyz="0 0 0" rpy="0 0 0"/>
                <mass value="2"/>
                <inertia ixx="0.03" ixy="0" ixz="0" iyy="0.03" iyz="0" izz="0.03" />
            </inertial>
            
            <visual>
                <origin xyz="0 0 0" rpy="0 0 0" />
                <geometry>
                    <mesh filename="package://ipa325_robot_descriptions/meshes/kr16/joint_3.stl" />
                </geometry>
                <material name="lbr-material">
                    <color rgba="${r} ${g} ${b} 1.0"/>
                </material>
            </visual>
            
            <collision>
                <origin xyz="0 0 0" rpy="0 0 0" />
                <geometry>
                    <mesh filename="package://ipa325_robot_descriptions/meshes/kr16/joint_3.stl" />
                </geometry>
            </collision>
        </link> 

        <!-- joint between arm_3_link and arm_4_link -->
        <joint name="${prefix}joint_4" type="revolute">
            <origin xyz="0.400 0.0 0.0" rpy="0 -${pi/2} 0" />
            <parent link="${prefix}link_3"/>
            <child link="${prefix}link_4"/>
            <axis xyz="0 0 1" />
            <dynamics damping="5" />
            <limit effort="100" velocity="1.9634" lower="-2.0943" upper="2.0943"/>
            <safety_controller k_position="20" k_velocity="25" soft_lower_limit="${-2.0943 + 0.01}" soft_upper_limit="${2.0943 - 0.01}" />
        </joint>

        <link name="${prefix}link_4">
            <inertial>
                <origin xyz="0 0 0" rpy="0 0 0"/>
                <mass value="2"/>
                <inertia ixx="0.03" ixy="0" ixz="0" iyy="0.03" iyz="0" izz="0.03" />
            </inertial>
            
            <visual>
                <origin xyz="0 0 0" rpy="0 0 0" />
                <geometry>
                    <mesh filename="package://ipa325_robot_descriptions/meshes/kr16/joint_4.stl" />
                </geometry>
                <material name="lbr-material">
                    <color rgba="${r} ${g} ${b} 1.0"/>
                </material>
            </visual>
            
            <collision>
                <origin xyz="0 0 0" rpy="0 0 0" />
                <geometry>
                    <mesh filename="package://ipa325_robot_descriptions/meshes/kr16/joint_4.stl" />
                </geometry>
            </collision>
        </link>

        <!-- joint between arm_4_link and arm_5_link -->
        <joint name="${prefix}joint_5" type="revolute">
            <origin xyz="0 0 -0.270" rpy="0 ${pi/2} 0" />
            <parent link="${prefix}link_4"/>
            <child link="${prefix}link_5"/>
            <axis xyz="0 0 1" />
            <dynamics damping="5" />
            <limit effort="100" velocity="1.9634" lower="-2.9670" upper="2.9670" />
            <safety_controller k_position="20" k_velocity="25" soft_lower_limit="${-2.9670 + 0.01}" soft_upper_limit="${2.9670 - 0.01}" />
        </joint>

        <link name="${prefix}link_5">
            <inertial>
                <origin xyz="0 0 0" rpy="0 0 0"/>
                <mass value="2"/>
                <inertia ixx="0.03" ixy="0" ixz="0" iyy="0.03" iyz="0" izz="0.03" />
            </inertial>
            
            <visual>
                <origin xyz="0 0 0" rpy="0 0 0" />
                <geometry>
                    <mesh filename="package://ipa325_robot_descriptions/meshes/kr16/joint_5.stl" />
                </geometry>
                <material name="lbr-material">
                    <color rgba="${r} ${g} ${b} 1.0"/>
                </material>
            </visual>
            
            <collision>
                <origin xyz="0 0 0" rpy="0 0 0" />
                <geometry>
                    <mesh filename="package://ipa325_robot_descriptions/meshes/kr16/joint_5.stl" />
                </geometry>
            </collision>
        </link>

        <!-- joint between arm_5_link and arm_6_link -->
        <joint name="${prefix}joint_6" type="revolute">
            <origin xyz="0.146 0 0" rpy="0 -${pi/2} 0" /> 
            <parent link="${prefix}link_5"/>
            <child link="${prefix}link_6"/>
            <axis xyz="0 0 1" />
            <dynamics damping="5" />
            <limit effort="30" velocity="1.9634" lower="-2.0943951" upper="2.0943951" />
            <safety_controller k_position="20" k_velocity="25" soft_lower_limit="${-2.0943951 + 0.01}" soft_upper_limit="${2.0943951 - 0.01}" />
        </joint>

        <link name="${prefix}link_6">
            <inertial>
                <origin xyz="0 0 0" rpy="0 0 0"/>
                <mass value="2"/>
                <inertia ixx="0.01" ixy="0" ixz="0" iyy="0.01" iyz="0" izz="0.01" />
            </inertial>
            
            <visual>
                <origin xyz="0 0 0" rpy="0 0 0" />
                <geometry>
                    <mesh filename="package://ipa325_robot_descriptions/meshes/kr16/joint_6.stl" />
                </geometry>
                <material name="lbr-material">
                    <color rgba="${r} ${g} ${b} 1.0"/>
                </material>
            </visual>
            
            <collision>
                <origin xyz="0 0 0" rpy="0 0 0" />
                <geometry>
                    <mesh filename="package://ipa325_robot_descriptions/meshes/kr16/joint_6.stl" />
                </geometry>
            </collision>
        </link>

        <joint name="${prefix}ee_joint" type="fixed" >
            <origin xyz="0 0 -0.012" rpy="${pi} 0 ${pi/2}" />
            <parent link="${prefix}link_6" />
            <child link="${prefix}ee" />
        </joint>

        <link name="${prefix}ee"/>

        <!-- include gazebo -->
        <xacro:kr16_gazebo name="${prefix}" />

        <!-- include transmission -->
        <xacro:kr16_transmission name="${prefix}" />

    </xacro:macro>

</robot>
